Workbook
Name Audit_Scores: [1]Data!$B$4:$B$7
Name Audit_Scores: #REF!

Sheet Audit Summary
F4: ISO 9001:2026 Readiness Checker - Audit Summary
D8: Address - ZIP/Post Code - Country | J8: Company Name | P8: Product
J13: Audit Conductor(s) | P13: Commodity
J18: Audit Date(s) | P18: ISO 9001 Quality Certificate/Number/Expiry Date (If Applicable)
D23: Clause 4: Context of the Organization | J23: Clause 5: Leadership and Commitment | P23: Clause 6: Planning
D24: 4.1 | E24: Understanding the organization and its context | F24: ='Audit Scoring Detail'!J10 -> 0
D25: 4.2 | E25: Understanding the needs and expectations of interested parties | F25: ='Audit Scoring Detail'!K10 -> 0 | J25: 5.1 | K25: Understanding the organization and its context | L25: ='Audit Scoring Detail'!K17 -> #REF! | P25: 6.1 | Q25: Actions to address risks and opportunities | R25: ='Audit Scoring Detail'!K24 -> #REF!
D26: 4.3 | E26: Determining the scope of the quality management system | F26: ='Audit Scoring Detail'!L10 -> 0 | J26: 5.2 | K26: Understanding the needs and expectations of interested parties | L26: ='Audit Scoring Detail'!L17 -> #REF! | P26: 6.2 | Q26: Quality objectives and planning to achieve them | R26: ='Audit Scoring Detail'!L24 -> #REF!
D27: 4.4 | E27: Quality management system and its processes | F27: ='Audit Scoring Detail'!M10 -> 0 | J27: 5.3 | K27: Determining the scope of the quality management system | L27: ='Audit Scoring Detail'!M17 -> #REF! | P27: 6.3 | Q27: Planning of changes | R27: ='Audit Scoring Detail'!M24 -> #REF!
D28: Major NC's | F28: =COUNTIF('ALL QUESTIONS'!E1:E20, 0) -> 19 | J28: Major NC's | L28: =COUNTIF('ALL QUESTIONS'!E21:E33, 0) -> 0 | P28: Major NC's | R28: =COUNTIF('ALL QUESTIONS'!E34:E48, 0) -> 0
D29: Minor NC's | F29: =COUNTIF('ALL QUESTIONS'!E1:E20, 1) -> 0 | J29: Minor NC's | L29: =COUNTIF('ALL QUESTIONS'!E21:E33, 1) -> 0 | P29: Minor NC's | R29: =COUNTIF('ALL QUESTIONS'!E34:E48, 1) -> 0
D30: OFI (Opportunities For Improvement) | F30: =COUNTIF('ALL QUESTIONS'!E1:E20, 2) -> 0 | J30: OFI (Opportunities For Improvement) | L30: =COUNTIF('ALL QUESTIONS'!E21:E33, 2) -> 0 | P30: OFI (Opportunities For Improvement) | R30: =COUNTIF('ALL QUESTIONS'!E34:E48, 2) -> 0
D31: Points Available: | F31: ='Audit Scoring Detail'!Q10 -> 57 | J31: Points Available: | L31: ='Audit Scoring Detail'!Q17 -> 39 | P31: Points Available: | R31: ='Audit Scoring Detail'!Q24 -> 45
D32: Total Points: | F32: ='Audit Scoring Detail'!R10 -> 0 | J32: Total Points: | L32: ='Audit Scoring Detail'!R17 -> #REF! | P32: Total Points: | R32: ='Audit Scoring Detail'!R24 -> #REF!
E33: Section Score: | F33: ='Audit Scoring Detail'!S10 -> 0 | K33: Section Score: | L33: ='Audit Scoring Detail'!S17 -> 0 | Q33: Section Score: | R33: ='Audit Scoring Detail'!S24 -> 0
D34: Compliance Status: | F34: ='Audit Scoring Detail'!E10 -> Failed | J34: Compliance Status: | L34: ='Audit Scoring Detail'!E17 -> Optimal | P34: Compliance Status: | R34: ='Audit Scoring Detail'!E24 -> Optimal
D38: Clause 7: Support | J38: Clause 8: Operation | P38: AUDIT SUMMARY
J39: 8.1 | K39: Operational planning and control | L39: ='Audit Scoring Detail'!G38 -> #REF!
J40: 8.2 | K40: Requirements for products and services | L40: ='Audit Scoring Detail'!H38 -> #REF!
D41: 7.1 | E41: Resources | F41: ='Audit Scoring Detail'!I31 -> #REF! | J41: 8.3 | K41: Design and development of products and services | L41: ='Audit Scoring Detail'!I38 -> #REF!
D42: 7.2 | E42: Competence | F42: ='Audit Scoring Detail'!J31 -> #REF! | J42: 8.4 | K42: Control of externally provided processes, products, and services | L42: ='Audit Scoring Detail'!J38 -> #REF!
D43: 7.3 | E43: Awareness | F43: ='Audit Scoring Detail'!K31 -> #REF! | J43: 8.5 | K43: Production and service provision | L43: ='Audit Scoring Detail'!K38 -> #REF!
D44: 7.4 | E44: Communication | F44: ='Audit Scoring Detail'!L31 -> #REF! | J44: 8.6 | K44: Release of products and services | L44: ='Audit Scoring Detail'!L38 -> #REF!
D45: 7.5 | E45: Documented information | F45: ='Audit Scoring Detail'!M31 -> #REF! | J45: 8.7 | K45: Control of nonconforming outputs | L45: ='Audit Scoring Detail'!M38 -> #REF!
D46: Major NC's | F46: =COUNTIF('ALL QUESTIONS'!E49:E70, 0) -> 0 | J46: Major NC's | L46: =COUNTIF('ALL QUESTIONS'!E71:E102, 0) -> 0
D47: Minor NC's | F47: =COUNTIF('ALL QUESTIONS'!E49:E70, 1) -> 0 | J47: Minor NC's | L47: =COUNTIF('ALL QUESTIONS'!E71:E102, 1) -> 0
D48: OFI (Opportunities For Improvement) | F48: =COUNTIF('ALL QUESTIONS'!E49:E70, 2) -> 0 | J48: OFI (Opportunities For Improvement) | L48: =COUNTIF('ALL QUESTIONS'!E71:E102, 2) -> 0
D49: Points Available: | F49: ='Audit Scoring Detail'!Q31 -> 66 | J49: Points Available: | L49: ='Audit Scoring Detail'!Q38 -> 96
D50: Total Points: | F50: ='Audit Scoring Detail'!R31 -> #REF! | J50: Total Points: | L50: ='Audit Scoring Detail'!R38 -> #REF!
E51: Section Score: | F51: ='Audit Scoring Detail'!S31 -> 0 | K51: Section Score: | L51: ='Audit Scoring Detail'!S38 -> 0
D52: Compliance Status: | F52: ='Audit Scoring Detail'!E31 -> Optimal | J52: Compliance Status: | L52: ='Audit Scoring Detail'!E38 -> Optimal
D56: Clause 9: Performance Evaluation | J56: Clause 10: Improvement
D57: 9.1 | E57: Monitoring, measurement, analysis and evaluation | F57: ='Audit Scoring Detail'!K45 -> #REF! | J57: 10.1 | K57: General (Improvement) | L57: ='Audit Scoring Detail'!K53 -> #REF!
D58: 9.2 | E58: Internal audit | F58: ='Audit Scoring Detail'!L45 -> #REF! | J58: 10.2 | K58: Nonconformity and corrective action | L58: ='Audit Scoring Detail'!L53 -> #REF!
D59: 9.3 | E59: Management review | F59: ='Audit Scoring Detail'!M45 -> #REF! | J59: 10.3 | K59: Continual improvement | L59: ='Audit Scoring Detail'!M53 -> #REF!
D60: Major NC's | F60: =COUNTIF('ALL QUESTIONS'!E104:E116, 0) -> 0 | J60: Major NC's | L60: =COUNTIF('ALL QUESTIONS'!E117:E128, 0) -> 0
D61: Minor NC's | F61: =COUNTIF('ALL QUESTIONS'!E104:E116, 1) -> 0 | J61: Minor NC's | L61: =COUNTIF('ALL QUESTIONS'!E117:E128, 1) -> 0
D62: OFI (Opportunities For Improvement) | F62: =COUNTIF('ALL QUESTIONS'!E104:E116, 2) -> 0 | J62: OFI (Opportunities For Improvement) | L62: =COUNTIF('ALL QUESTIONS'!E117:E128, 2) -> 0
D63: Points Available: | F63: ='Audit Scoring Detail'!Q45 -> 42 | J63: Points Available: | L63: ='Audit Scoring Detail'!Q53 -> 36
D64: Total Points: | F64: ='Audit Scoring Detail'!R45 -> #REF! | J64: Total Points: | L64: ='Audit Scoring Detail'!R53 -> #REF!
...

Sheet Audit Scoring Detail
D4: Scoring Detail
D8: Clause 4: Context of the Organization | Q8: Number of points available | R8: Total Points | S8: Awarded Points
J9: 4.1 | K9: 4.2 | L9: 4.3 | M9: 4.4
D10: Status | E10: =IF(COUNTA('ALL QUESTIONS'!E2:E20) < ROWS('ALL QUESTIONS'!E2:E20), "", IF(COUNTIF('ALL QUESTIONS'!E2:E20, 0) > 0, "Failed", IF(COUNTIF('ALL QUESTIONS'!E2:E20, 1) > 0, "Partial", IF(COUNTIF('ALL QUESTIONS'!E2:E20, 2) > 0, "Ready", "Optimal")))) -> Failed | I10: Score | J10: =SUM('Clause 4'!H8:H11) -> 0 | K10: =SUM('Clause 4'!H18:H22) -> 0 | L10: =SUM('Clause 4'!H29:H32) -> 0 | M10: =SUM('Clause 4'!H39:H44) -> 0 | Q10: =SUM(J11:M11) -> 57 | R10: =SUM(J10:M10) -> 0 | S10: =IF(ISERROR(R10/(Q10)),0,(R10/(Q10))) -> 0
I11: Total | J11: 12 | K11: 15 | L11: 12 | M11: 18
D15: Clause 5: Leadership and Commitment | Q15: Number of points available | R15: Total Points | S15: Awarded Points
K16: 5.1 | L16: 5.2 | M16: 5.3
D17: Status | E17: =IF(COUNTA('ALL QUESTIONS'!E21:E33) < ROWS('ALL QUESTIONS'!E21:E33), "", IF(COUNTIF('ALL QUESTIONS'!E21:E33, 0) > 0, "Failed", IF(COUNTIF('ALL QUESTIONS'!E21:E33, 1) > 0, "Partial", IF(COUNTIF('ALL QUESTIONS'!E21:E33, 2) > 0, "Ready", "Optimal")))) -> Optimal | J17: Score | K17: =SUM(#REF!) -> #REF! | L17: =SUM(#REF!) -> #REF! | M17: =SUM(#REF!) -> #REF! | Q17: =SUM(K18:M18) -> 39 | R17: =SUM(K17:M17) -> #REF! | S17: =IF(ISERROR(R17/(Q17)),0,(R17/(Q17))) -> 0
J18: Total | K18: 12 | L18: 12 | M18: 15
D22: Clause 6: Planning | Q22: Number of points available | R22: Total Points | S22: Awarded Points
K23: 6.1 | L23: 6.2 | M23: 6.3
D24: Status | E24: =IF(COUNTA('ALL QUESTIONS'!E34:E48) < ROWS('ALL QUESTIONS'!E34:E48), "", IF(COUNTIF('ALL QUESTIONS'!E34:E48, 0) > 0, "Failed", IF(COUNTIF('ALL QUESTIONS'!E34:E48, 1) > 0, "Partial", IF(COUNTIF('ALL QUESTIONS'!E34:E48, 2) > 0, "Ready", "Optimal")))) -> Optimal | J24: Score | K24: =SUM(#REF!) -> #REF! | L24: =SUM(#REF!) -> #REF! | M24: =SUM(#REF!) -> #REF! | Q24: =SUM(K25:M25) -> 45 | R24: =SUM(K24:M24) -> #REF! | S24: =IF(ISERROR(R24/(Q24)),0,(R24/(Q24))) -> 0
J25: Total | K25: 18 | L25: 12 | M25: 15
D29: Clause 7: Support | Q29: Number of points available | R29: Total Points | S29: Awarded Points
I30: 7.1 | J30: 7.2 | K30: 7.3 | L30: 7.4 | M30: 7.5
D31: Status | E31: =IF(COUNTA('ALL QUESTIONS'!E49:E70) < ROWS('ALL QUESTIONS'!E49:E70), "", IF(COUNTIF('ALL QUESTIONS'!E49:E70, 0) > 0, "Failed", IF(COUNTIF('ALL QUESTIONS'!E49:E70, 1) > 0, "Partial", IF(COUNTIF('ALL QUESTIONS'!E49:E70, 2) > 0, "Ready", "Optimal")))) -> Optimal | H31: Score | I31: =SUM(#REF!) -> #REF! | J31: =SUM(#REF!) -> #REF! | K31: =SUM(#REF!) -> #REF! | L31: =SUM(#REF!) -> #REF! | M31: =SUM(#REF!) -> #REF! | Q31: =SUM(I32:M32) -> 66 | R31: =SUM(I31:M31) -> #REF! | S31: =IF(ISERROR(R31/(Q31)),0,(R31/(Q31))) -> 0
H32: Total | I32: 12 | J32: 15 | K32: 12 | L32: 12 | M32: 15
D36: Clause 8: Operation | Q36: Number of points available | R36: Total Points | S36: Awarded Points
G37: 8.1 | H37: 8.2 | I37: 8.3 | J37: 8.4 | K37: 8.5 | L37: 8.6 | M37: 8.7
D38: Status | E38: =IF(COUNTA('ALL QUESTIONS'!E71:E102) < ROWS('ALL QUESTIONS'!E71:E102), "", IF(COUNTIF('ALL QUESTIONS'!E71:E102, 0) > 0, "Failed", IF(COUNTIF('ALL QUESTIONS'!E71:E102, 1) > 0, "Partial", IF(COUNTIF('ALL QUESTIONS'!E71:E102, 2) > 0, "Ready", "Optimal")))) -> Optimal | F38: Score | G38: =SUM(#REF!) -> #REF! | H38: =SUM(#REF!) -> #REF! | I38: =SUM(#REF!) -> #REF! | J38: =SUM(#REF!) -> #REF! | K38: =SUM(#REF!) -> #REF! | L38: =SUM(#REF!) -> #REF! | M38: =SUM(#REF!) -> #REF! | Q38: =SUM(G39:M39) -> 96 | R38: =SUM(G38:M38) -> #REF! | S38: =IF(ISERROR(R38/(Q38)),0,(R38/(Q38))) -> 0
F39: Total | G39: 15 | H39: 12 | I39: 15 | J39: 12 | K39: 15 | L39: 12 | M39: 15
D43: Clause 9: Performance Evaluation | Q43: Number of points available | R43: Total Points | S43: Awarded Points
K44: 9.1 | L44: 9.2 | M44: 9.3
D45: Status | E45: =IF(COUNTA('ALL QUESTIONS'!E104:E116) < ROWS('ALL QUESTIONS'!E104:E116), "", IF(COUNTIF('ALL QUESTIONS'!E104:E116, 0) > 0, "Failed", IF(COUNTIF('ALL QUESTIONS'!E104:E116, 1) > 0, "Partial", IF(COUNTIF('ALL QUESTIONS'!E104:E116, 2) > 0, "Ready", "Optimal")))) -> Optimal | J45: Score | K45: =SUM(#REF!) -> #REF! | L45: =SUM(#REF!) -> #REF! | M45: =SUM(#REF!) -> #REF! | Q45: =SUM(K46:M46) -> 42 | R45: =SUM(K45:M45) -> #REF! | S45: =IF(ISERROR(R45/(Q45)),0,(R45/(Q45))) -> 0
J46: Total | K46: 12 | L46: 15 | M46: 15
D51: Clause 10: Improvement | Q51: Number of points available | R51: Total Points | S51: Awarded Points
K52: 10.01 | L52: 10.02 | M52: 10.03
D53: Status | E53: =IF(COUNTA('ALL QUESTIONS'!E117:E128) < ROWS('ALL QUESTIONS'!E117:E128), "", IF(COUNTIF('ALL QUESTIONS'!E117:E128, 0) > 0, "Failed", IF(COUNTIF('ALL QUESTIONS'!E117:E128, 1) > 0, "Partial", IF(COUNTIF('ALL QUESTIONS'!E117:E128, 2) > 0, "Ready", "Optimal")))) -> Optimal | J53: Score | K53: =SUM(#REF!) -> #REF! | L53: =SUM(#REF!) -> #REF! | M53: =SUM(#REF!) -> #REF! | Q53: =SUM(K54:M54) -> 36 | R53: =SUM(K53:M53) -> #REF! | S53: =IF(ISERROR(R53/(Q53)),0,(R53/(Q53))) -> 0
J54: Total | K54: 9 | L54: 15 | M54: 12
B60: Score | F60: Meaning | I60: ISO 9001 Compliance | L60: Notes | V60: Type | W60: Dsescription | Y60: Dsescription
B63: 3 | F63: Advanced / Best Practise | I63: Compliant and Exceeding | L63: Goes beyond ISO 9001 - proactively, optimized, integrated | V63: Major NC (0) | W63: A significant failure to meet a requirement or a systemic issue (e.g., a clause not implemented at all) | Y63: Certification may be denied or suspended until corrective action is verified
B66: 2 | F66: Formal / Adequate | I66: Compliant | L66: Meets ISO 9001 requirements - processes are defined, documented, and consistently followed | V66: Minor NC (1) | W66: A small lapse or isolated issue (e.g., a missing signature, inconsistent application of a process) | Y66: Cerification can be granted or maintained, provided correction action is taken within a set time (typically 30-90 days)
B69: 1 | F69: Partially Compliant | I69: Partially Compliant | L69: Not sufficient for certification - needs formalization or consistency | V69: Observation / Opportunities for Improvement (OFI) (2) | W69: Not a noncompliance, but areas that could improve or become problematic | Y69: No impact on certification
B72: 0 | F72: Non-Compliant | I72: Non-compliant | L72: Fails to meet the clause requirement

Sheet Clause 4
C2: Clause 4: Context of the Organization
C5: 4.1 Understanding the organization and its context
D6: Taking a step back to look at what's happening inside and outside the business that could affect how it operates, so you can plan and manage more effectively.
D7: # | E7: Question | F7: Evidence Required | G7: Scoring Criteria | H7: Status | I7: Observations | J7: Action Required
D8: 4.1A | E8: Have internal issues (e.g. culture, resources, processes, performance, sustainability, and resilience factors) affecting your QMS been identified and documented?” | F8: • SWOT analysis or equivalent internal evaluation • Internal audit or business risk reports identifying internal issues • Business performance and sustainability reports • Resource, process, and capability assessments • Evidence of consideration of resilience or adaptability of processes | G8: * (3) As 2 plus reviewed during management review or linked to performance/resilience metrics * (2) Documented SWOT or equivalent analysis is available and recent * (1) Informal understanding, not written down * (0) No evidence | J8: =IF( H8="", "", IF( AND(H8>=0, H8<=1), "Going from 0–1 to 2" & CHAR(10) & "✅ Write down internal issues such as skills gaps, resource shortages, sustainability or resilience challenges." & CHAR(10) & "✅ Do a simple SWOT (Strengths, Weaknesses, Opportunities, Threats) or context analysis including resilience and sustainability factors.", IF( H8=2, "Going from 2 to 3" & CHAR(10) & "✅ Use this list in management or strategic reviews to link issues with performance and resilience goals." & CHAR(10) & "✅ Track impact using metrics (e.g., resource utilization, process uptime, staff turnover, sustainability KPIs).", "" ) ) )
D9: 4.1B | E9: Have external issues (e.g. legal, technological, social, environmental, competitive, or economic) relevant to your organization’s purpose and strategic direction been identified? | F9: • PESTLE or STEEPLE analysis (including Environmental and Social factors) • Regulatory and compliance tracking logs • Industry benchmarking or trend analysis • Market or stakeholder research • Reports considering climate, sustainability, or supply-chain resilience factors | G9: * (3) As (2) plus trends are monitored and used in strategic and risk planning * (2) External issues formally documented in a PESTLE/ STEEPLE or similar * (1) General awareness only, no records * (0) No evidence | J9: =IF( H9="", "", IF( AND(H9>=0, H9<=1), "Going from 0–1 to 2" & CHAR(10) & "✅ Create or update a PESTLE or STEEPLE list (Political, Economic, Social, Technological, Legal, Environmental) covering current and future external issues." & CHAR(10) & "✅ Record relevant info from regulators, suppliers, customers, or industry news.", IF( H9=2, "Going from 2 to 3" & CHAR(10) & "✅ Review and update this list every 6–12 months." & CHAR(10) & "✅ Link insights to business or risk planning (e.g., supply-chain resilience, sustainability trends).", "" ) ) )
D10: 4.1C | E10: Are internal and external issues, including sustainability and resilience factors, reviewed regularly and updated as part of business or management reviews? | F10: • Scheduled review calendar or planning timeline • Minutes from management or strategic review meetings • Updated SWOT/PESTLE/ STEEPLE documentation • Evidence of periodic review cycles linked to business, risk, or sustainability planning | G10: * (3) As (2) plus reviews are formally scheduled, documented, and linked to strategic or risk planning (e.g., annually) * (2) Issues reviewed during meetings, with some documented evidence * (1) Issues occasionally discussed but without structure or record * (0) No evidence | J10: =IF( H10="", "", IF( AND(H10>=0, H10<=1), "Going from 0–1 to 2" & CHAR(10) & "✅ Set a reminder (e.g., quarterly or yearly) to review internal and external issues, including sustainability or risk factors." & CHAR(10) & "✅ Record notes or action items from these discussions.", IF( H10=2, "Going from 2 to 3" & CHAR(10) & "✅ Add this review to your management or strategic review agenda." & CHAR(10) & "✅ Keep a log or calendar showing when reviews take place and what changed.", "" ) ) )
D11: 4.1D | E11: Are identified internal and external issues, including sustainability and resilience factors, used to inform risk and opportunity planning (Clause 6.1)? | F11: • Risk and opportunity register referencing context factors • Strategic or business plan aligned with identified issues • Action plans addressing internal/external risks and opportunities • Management review outputs linking context, risk, and planning • Evidence that sustainability or resilience risks are considered | G11: * (3) As (2) plus linkage is documented, traceable, and reviewed in management review * (2) Some identified issues inform the risk/opportunity log * (1) Risks documented but not clearly tied to internal/external issues * (0) No evidence | J11: =IF( H11="", "", IF( AND(H11>=0, H11<=1), "Going from 0–1 to 2" & CHAR(10) & "✅ Start a simple risk and opportunity register (spreadsheet or log)." & CHAR(10) & "✅ Note how each risk or opportunity links to an internal/external issue — including sustainability or resilience factors.", IF( H11=2, "Going from 2 to 3" & CHAR(10) & "✅ Link your risk register to business or improvement plans." & CHAR(10) & "✅ Track how actions reduce or strengthen resilience over time, and discuss in management reviews.", "" ) ) )
D15: 4.2 Understanding the needs and expectations of interested parties
D16: Identifying everyone who has an interest in your business — like customers, employees, suppliers, or regulators — and understanding what they expect from you.
D17: # | E17: Question | F17: Evidence Required | G17: Scoring Criteria | H17: Status | I17: Observations | J17: Action Required
D18: 4.2A | E18: Have the relevant interested parties, including those linked to sustainability, resilience, and long-term success, been identified (e.g., customers, regulators, suppliers, staff, communities)? | F18: • Stakeholder register or mapping document • Organization chart showing stakeholder connections • Meeting notes or planning sessions identifying stakeholders • Documented criteria or rationale for stakeholder relevance • Inclusion of sustainability- or community-related stakeholders | G18: * (3) As (2) plus stakeholder roles and needs integrated into strategic and sustainability objectives * (2) Formal stakeholder list with rationale is documented * (1) Informal awareness of some key stakeholders * (0) No evidence | J18: =IF( H18="", "", IF( AND(H18>=0, H18<=1), "Going from 0–1 to 2" & CHAR(10) & "✅ Make a list of people or groups who affect or are affected by your business — e.g., customers, staff, suppliers, auditors, local authorities, and community groups." & CHAR(10) & "✅ Note why each one matters (their expectations or impact on quality, sustainability, or resilience).", IF( H18=2, "Going from 2 to 3" & CHAR(10) & "✅ Review and update this list at least once a year or when major changes happen." & CHAR(10) & "✅ Link stakeholder needs to your business objectives or sustainability plans.", "" ) ) )
D19: 4.2B | E19: Have the relevant needs, expectations, and requirements of interested parties (including sustainability, compliance, and resilience aspects) been identified and documented? | F19: • Stakeholder needs and expectations matrix or register • Results from surveys, interviews, or feedback reviews • Regulatory requirement listings or legal registers • Documented stakeholder communication or engagement records • Evidence that needs include sustainability or resilience expectations | G19: * (3) As (2) plus records are regularly updated to reflect changing or emerging expectations * (2) Clear documentation of stakeholder needs, expectations, and applicable requirements * (1) Some informal understanding or notes, but not documented * (0) No evidence | J19: =IF( H19="", "", IF( AND(H19>=0, H19<=1), "Going from 0–1 to 2" & CHAR(10) & "✅ For each person or group on your list, write down what they expect from you (for example: customers expect quality, staff want safety, regulators want compliance, communities expect responsible practices)." & CHAR(10) & "✅ Even a simple table or stakeholder matrix is fine.", IF( H19=2, "Going from 2 to 3" & CHAR(10) & "✅ Review and update these needs regularly (for example, once a year or when major changes happen)." & CHAR(10) & "✅ Use this information when setting objectives, assessing risks, or planning improvements.", "" ) ) )
D20: 4.2C | E20: Are changes in stakeholder needs, expectations, and requirements, including compliance or sustainability factors, monitored regularly? | F20: • Records of ongoing customer feedback or stakeholder engagement • Regulatory and legal update logs • Management review minutes showing stakeholder discussions • Formal schedule or log for reviewing stakeholder expectations • Evidence of updates due to new laws, customer demands, or sustainability shifts | G20: * (3) As (2) plus a documented and scheduled review process with resulting actions * (2) Documented evidence that reviews or updates occur periodically * (1) Awareness of changes, but no structured review or documentation * (0) No evidence | J20: =IF( H20="", "", IF( AND(H20>=0, H20<=1), "Going from 0–1 to 2" & CHAR(10) & "✅ Every few months, check if stakeholder expectations have changed (e.g., customer needs, legal or sustainability requirements)." & CHAR(10) & "✅ Make a quick note of what changed and when.", IF( H20=2, "Going from 2 to 3" & CHAR(10) & "✅ Add this review to management meetings or planning reviews." & CHAR(10) & "✅ Keep a simple log of reviews, what changed, and any follow-up actions.", "" ) ) )
D21: 4.2D | E21: Are stakeholder needs, expectations, and requirements, including compliance, sustainability, and performance factors, considered in the QMS scope and planning? | F21: • QMS scope statement that references stakeholder needs or expectations • Strategic or business plans showing alignment with external or customer requirements • Risk and opportunity assessments reflecting stakeholder input • Management review records linking expectations to decisions or improvements | G21: * (3) Clear and traceable links between stakeholder needs and QMS scope/planning documents * (2) Documented evidence that stakeholder needs are considered in scope or planning * (1) Some informal or verbal consideration only * (0) No evidence | J21: =IF( H21="", "", IF( AND(H21>=0, H21<=1), "Going from 0–1 to 2" & CHAR(10) & "✅ When setting goals or planning improvements, refer to what key groups expect (e.g. include 'on-time delivery' if a client expects it)." & CHAR(10) & "✅ Add short notes showing where these expectations are considered.", IF( H21=2, "Going from 2 to 3" & CHAR(10) & "✅ Show clear links between stakeholder needs and your QMS scope or plans (e.g. 'We upgraded packaging due to customer feedback')." & CHAR(10) & "✅ Keep simple evidence in meeting notes, planning documents, or reviews.", "" ) ) )
D22: 4.2E | E22: Are stakeholder needs, expectations, and requirements, including customer, regulatory, sustainability, and community priorities, communicated to relevant staff and departments? | F22: • Training or onboarding materials covering stakeholder or customer requirements • Internal communication plans or staff briefings on quality, compliance, or sustainability goals • Internal newsletters, bulletins, or dashboards sharing stakeholder priorities • Meeting minutes or awareness sessions confirming communication of stakeholder expectations | G22: * (3) Evidence of communication across departments, including feedback or awareness checks * (2) Stakeholder needs and expectations are shared with relevant teams or roles * (1) Communication is limited to a few individuals or informal conversations * (0) No evidence | J22: =IF( H22="", "", IF( AND(H22>=0, H22<=1), "Going from 0–1 to 2" & CHAR(10) & "✅ Tell your team what matters to key groups (for example: customers, regulators, suppliers) through meetings, memos, or training." & CHAR(10) & "✅ Use checklists, posters, or short updates to reinforce expectations.", IF( H22=2, "Going from 2 to 3" & CHAR(10) & "✅ Include stakeholder priorities in training content, job roles, or team dashboards." & CHAR(10) & "✅ Ask teams during reviews if they understand who your business serves and what their expectations are.", "" ) ) )
D26: 4.3 Determining the scope of the quality management system
D27: Clearly defining what parts of your business are covered by the quality management system, based on what you do, who you serve, and any rules or requirements you must follow.
D28: # | E28: Question | F28: Evidence Required | G28: Scoring Criteria | H28: Status | I28: Observations | J28: Action Required
D29: 4.3A | E29: Has the organization defined the boundaries and applicability of its quality management system, including how it aligns with its context, interested parties, and strategic direction? | F29: • Documented QMS scope statement • Description of organizational, physical, or operational boundaries • Product/service coverage details • Organization charts showing included areas or functions • Notes showing alignment with context and stakeholder expectations | G29: (3) As (2) plus the scope is mapped to processes, sites, and responsibilities, showing clear alignment with business strategy (2) Formal scope document defines boundaries and applicability clearly (1) Informal or partially documented understanding of scope (0) No evidence | J29: =IF( H29="", "", IF( AND(H29>=0, H29<=1), "Going from 0–1 to 2" & CHAR(10) & "✅ Write down what your quality system covers." & CHAR(10) & "Example: “Our QMS applies to the design, production, and delivery of handmade furniture.”" & CHAR(10) & "✅ Include where it applies (e.g., locations, departments, or product lines).", IF( H29=2, "Going from 2 to 3" & CHAR(10) & "✅ Add clear reasons for what’s included or excluded." & CHAR(10) & "Example: “Installation services are excluded because we don’t perform them.”" & CHAR(10) & "✅ Show how this scope aligns with your business goals and stakeholder needs.", "" ) ) )
D30: 4.3B | E30: Are all relevant products and services, including new or evolving offerings, clearly included within the scope of the QMS | F30: • List of all current products and services • Mapping between offerings and QMS processes or departments • Marketing materials or website descriptions aligned with the documented scope • Records showing periodic review of scope coverage when new products or services are introduced | G30: (3) As (2) plus regular reviews confirm all current and new offerings remain within QMS coverage (2) Clear documentation aligning QMS scope with actual products and services provided (1) Scope partially covers offerings or is outdated (0) No evidence | J30: =IF( H30="", "", IF( AND(H30>=0, H30<=1), "Going from 0–1 to 2" & CHAR(10) & "✅ Make sure every product or service you deliver is included in your QMS scope or clearly excluded with a reason." & CHAR(10) & "✅ Avoid using vague terms like 'everything' — be specific about what’s covered.", IF( H30=2, "Going from 2 to 3" & CHAR(10) & "✅ Review your offerings regularly and ensure they match your scope." & CHAR(10) & "✅ Update your scope whenever you add or change a product or service, and check that your website and marketing match it.", "" ) ) )
D31: 4.3C | E31: Is the QMS scope documented, maintained, and easily available to relevant stakeholders, including employees, auditors, and external parties where appropriate? | F31: • Scope included in the quality manual or official QMS documentation • Version-controlled and approved scope statement • Accessible location (intranet, shared drive, or public website) • Evidence that the scope is shared during onboarding, audits, or management reviews | G31: (3) As (2) plus the scope is actively communicated (e.g., onboarding, training, or internal communication) (2) Scope is clearly documented and available to relevant personnel or auditors (1) Scope exists but is outdated, incomplete, or hard to locate (0) No evidence | J31: =IF( H31="", "", IF( AND(H31>=0, H31<=1), "Going from 0–1 to 2" & CHAR(10) & "✅ Add your scope to a quality manual, policy document, or a simple controlled file." & CHAR(10) & "✅ Make sure it’s easy to find if someone asks to see it.", IF( H31=2, "Going from 2 to 3" & CHAR(10) & "✅ Publish or share the scope on your intranet, shared drive, or company handbook." & CHAR(10) & "✅ Keep it version-controlled and review it when your operations or structure change.", "" ) ) )
D32: 4.3D | E32: Is the QMS scope communicated to relevant stakeholders, including employees, auditors, and external interested parties where appropriate? | F32: • Onboarding or induction materials referencing QMS scope • Internal communications (emails, briefings, posters, or team meetings) • Evidence that auditors and key stakeholders can easily access the scope • Audit or awareness training materials showing scope coverage | G32: (3) As (2) plus the communication is reinforced through awareness checks, refresher training, or briefings (2) Scope is shared with key personnel and auditors in a consistent, documented way (1) Scope is shared informally (e.g., verbally or inconsistently) (0) No evidence | J32: =IF( H32="", "", IF( AND(H32>=0, H32<=1), "Going from 0–1 to 2" & CHAR(10) & "✅ Tell your team what the QMS covers and why it matters." & CHAR(10) & "✅ Make sure auditors can easily see or be given a copy of the scope.", IF( H32=2, "Going from 2 to 3" & CHAR(10) & "✅ Add scope awareness to onboarding and refresher training." & CHAR(10) & "✅ Mention the scope in management review or pre-audit meetings.", "" ) ) )
D36: 4.4 Quality management system and its processes
D37: Set up and manage the key processes that keep your business running smoothly, so you can consistently meet customer and stakeholder expectations.
D38: # | E38: Question | F38: Evidence Required | G38: Scoring Criteria | H38: Status | I38: Observations | J38: Action Required
D39: 4.4A | E39: Has the organization determined the processes needed for the QMS and their application throughout the organization? | F39: • Documented list or map of all QMS processes • Defined scope and purpose for each process • Process flowcharts or interaction diagrams • Evidence of alignment between processes and organizational objectives | G39: (3) As (2) plus process responsibilities and owners are clearly defined (2) Documented and complete list of all QMS processes exists (1) Partial or informal list of processes exists (0) No evidence | J39: =IF( H39="", "", IF( AND(H39>=0, H39<=1), "Going from 0–1 to 2" & CHAR(10) & "✅ Write down your main business processes — e.g., Sales, Delivery, Customer Service." & CHAR(10) & "✅ Show how each connects or flows to the next (a simple list or map works).", IF( H39=2, "Going from 2 to 3" & CHAR(10) & "✅ Create a simple diagram or flowchart showing how all processes interact." & CHAR(10) & "✅ Explain how each process supports your quality objectives and outcomes.", "" ) ) )
D40: 4.4B | E40: Are the inputs and expected outputs of each process defined? | F40: • Process input/output documentation or templates • Process flow diagrams or SIPOC models (possibly within FMEA) • Evidence of performance measurement or tracking | G40: (3) As (2) plus inputs and outputs are validated and monitored (2) Documented inputs and outputs for each process (1) Inputs and outputs are known but not formally documented (0) No evidence | J40: =IF( H40="", "", IF( AND(H40>=0, H40<=1), "Going from 0–1 to 2" & CHAR(10) & "✅ For each process, note what it needs to start (input) and what it should produce (output)." & CHAR(10) & "Example: 'Delivery needs an invoice and stock; output is a shipped product.'", IF( H40=2, "Going from 2 to 3" & CHAR(10) & "✅ Use these definitions to identify and fix weak spots (e.g., 'if inputs are late, production slows down')." & CHAR(10) & "✅ Keep the information in a shared document or process guide so everyone can access it.", "" ) ) )
D41: 4.4C | E41: Have responsibilities and authorities for each process been assigned? | F41: • RACI matrices or responsibility charts • Job descriptions aligning with process ownership • Training or role assignment records • Org chart with process responsibility overlay | G41: * (3) As 2 plus cross-functional roles clarified and integrated * (2) Documented assignment of responsibilities per process * (1) Responsibility assigned informally * (0) No evidence | J41: =IF( H41="", "", IF( AND(H41>=0, H41<=1), "Going from 0–1 to 2" & CHAR(10) & "✅ Assign someone to be responsible for each main process." & CHAR(10) & "✅ Write it down — for example, in a RACI chart, role sheet, or job description.", IF( H41=2, "Going from 2 to 3" & CHAR(10) & "✅ Define backup roles or escalation paths (e.g., 'if the process owner is away, the deputy takes over')." & CHAR(10) & "✅ Link this to your training or competency plans so people are prepared for their roles.", "" ) ) )
D42: 4.4D | E42: Are performance indicators or methods for measuring the processes established? | F42: • KPIs or metrics per process • Monitoring logs, dashboards, or scorecards • Reports from internal audits or performance reviews • Quality objectives linked to process outputs | G42: * (3) As 2 plus real-time tracking and proactive actions * (2) Documented metrics with evidence of use * (1) Metrics mentioned but not monitored consistently * (0) No evidence | J42: =IF( H42="", "", IF( AND(H42>=0, H42<=1), "Going from 0–1 to 2" & CHAR(10) & "✅ Pick one or two simple measures for each key process (e.g., 'delivery time', 'error rate', 'customer satisfaction')." & CHAR(10) & "✅ Track them at least monthly to see how you’re performing.", IF( H42=2, "Going from 2 to 3" & CHAR(10) & "✅ Set clear goals or thresholds (e.g., 'delivery within 3 days', 'less than 2% rework')." & CHAR(10) & "✅ Use graphs or dashboards to monitor trends and take proactive action when results dip.", "" ) ) )
D43: 4.4E | E43: Are risks and opportunities for each process identified, documented, and addressed to enhance performance and resilience? | F43: • Risk registers per process or department • Risk mitigation or improvement action plans • Process-level SWOT or FMEA analyses • Management review records showing risk-based decisions • Evidence of follow-up and continuous improvement | G43: (3) As (2) plus evidence of ongoing monitoring and improvement actions based on risk reviews (2) Documented risks and opportunities with defined actions or controls (1) Risks or opportunities are acknowledged but not formally documented (0) No evidence | J43: =IF( H43="", "", IF( AND(H43>=0,H43<=1), "Going from 0–1 to 2" & CHAR(10) & "✅ Make a list of what could go wrong in each process (risks) and where you could improve (opportunities)." & CHAR(10) & "✅ Keep it simple, just a few key points per process.", IF( H43=2, "Going from 2 to 3" & CHAR(10) & "✅ Link these risks and opportunities to your improvement or action plans." & CHAR(10) & "✅ Review and update your list during team or management meetings, and note any progress made.", "" ) ) )
D44: 4.4F | E44: Are processes regularly reviewed, maintained, and improved as part of the QMS to support performance, resilience, and continual improvement? | F44: • Continual improvement logs or action registers • Internal audit and corrective action records • Lessons-learned documentation • Records of management review decisions that affect processes • Evidence of process changes made to improve efficiency, sustainability, or resilience | G44: (3) As (2) plus evidence of trend analysis and proactive improvement actions (2) Regular process reviews and updates are documented (1) Improvements are ad hoc or undocumented (0) No evidence | J44: =IF( H44="", "", IF( AND(H44>=0,H44<=1), "Going from 0–1 to 2" & CHAR(10) & "✅ Keep a simple log to track problems, changes, and improvements for each process." & CHAR(10) & "✅ Do regular reviews (e.g., annually or quarterly) to check if each process still performs as expected.", IF( H44=2, "Going from 2 to 3" & CHAR(10) & "✅ Use data to identify trends or recurring issues (e.g., complaints, delays, nonconformities)." & CHAR(10) & "✅ Record planned improvements and review their results in management meetings.", "" ) ) )

Sheet Action Plan
D4: Action Plan
D8: No. | E8: Section Ref. | F8: Section Score | G8: Question | H8: Observations | I8: Actions
D9: 1 | E9: =IF(ISERROR(VLOOKUP(D9,'ALL QUESTIONS'!B1:G128,2,FALSE)),"",(VLOOKUP(D9,'ALL QUESTIONS'!B1:G128,2,FALSE))) | F9: =IF(ISERROR(VLOOKUP(D9,'ALL QUESTIONS'!B1:G128,4,FALSE)),"",(VLOOKUP(D9,'ALL QUESTIONS'!B1:G128,4,FALSE))) | G9: =IF(ISERROR(VLOOKUP(D9,'ALL QUESTIONS'!B1:G128,3,FALSE)),"",(VLOOKUP(D9,'ALL QUESTIONS'!B1:G128,3,FALSE))) | H9: =IF(ISERROR(VLOOKUP(D9,'ALL QUESTIONS'!B1:G128,5,FALSE)),"",(VLOOKUP(D9,'ALL QUESTIONS'!B1:G128,5,FALSE))) | I9: =IF(ISERROR(VLOOKUP(D9,'ALL QUESTIONS'!B1:G128,6,FALSE)),"",(VLOOKUP(D9,'ALL QUESTIONS'!B1:G128,6,FALSE)))
D10: 2 | E10: =IF(ISERROR(VLOOKUP(D10,'ALL QUESTIONS'!B2:G129,2,FALSE)),"",(VLOOKUP(D10,'ALL QUESTIONS'!B2:G129,2,FALSE))) | F10: =IF(ISERROR(VLOOKUP(D10,'ALL QUESTIONS'!B2:G129,4,FALSE)),"",(VLOOKUP(D10,'ALL QUESTIONS'!B2:G129,4,FALSE))) | G10: =IF(ISERROR(VLOOKUP(D10,'ALL QUESTIONS'!B2:G129,3,FALSE)),"",(VLOOKUP(D10,'ALL QUESTIONS'!B2:G129,3,FALSE))) | H10: =IF(ISERROR(VLOOKUP(D10,'ALL QUESTIONS'!B2:G129,5,FALSE)),"",(VLOOKUP(D10,'ALL QUESTIONS'!B2:G129,5,FALSE))) | I10: =IF(ISERROR(VLOOKUP(D10,'ALL QUESTIONS'!B2:G129,6,FALSE)),"",(VLOOKUP(D10,'ALL QUESTIONS'!B2:G129,6,FALSE)))
D11: 3 | E11: =IF(ISERROR(VLOOKUP(D11,'ALL QUESTIONS'!B3:G130,2,FALSE)),"",(VLOOKUP(D11,'ALL QUESTIONS'!B3:G130,2,FALSE))) | F11: =IF(ISERROR(VLOOKUP(D11,'ALL QUESTIONS'!B3:G130,4,FALSE)),"",(VLOOKUP(D11,'ALL QUESTIONS'!B3:G130,4,FALSE))) | G11: =IF(ISERROR(VLOOKUP(D11,'ALL QUESTIONS'!B3:G130,3,FALSE)),"",(VLOOKUP(D11,'ALL QUESTIONS'!B3:G130,3,FALSE))) | H11: =IF(ISERROR(VLOOKUP(D11,'ALL QUESTIONS'!B3:G130,5,FALSE)),"",(VLOOKUP(D11,'ALL QUESTIONS'!B3:G130,5,FALSE))) | I11: =IF(ISERROR(VLOOKUP(D11,'ALL QUESTIONS'!B3:G130,6,FALSE)),"",(VLOOKUP(D11,'ALL QUESTIONS'!B3:G130,6,FALSE)))
D12: 4 | E12: =IF(ISERROR(VLOOKUP(D12,'ALL QUESTIONS'!B4:G131,2,FALSE)),"",(VLOOKUP(D12,'ALL QUESTIONS'!B4:G131,2,FALSE))) | F12: =IF(ISERROR(VLOOKUP(D12,'ALL QUESTIONS'!B4:G131,4,FALSE)),"",(VLOOKUP(D12,'ALL QUESTIONS'!B4:G131,4,FALSE))) | G12: =IF(ISERROR(VLOOKUP(D12,'ALL QUESTIONS'!B4:G131,3,FALSE)),"",(VLOOKUP(D12,'ALL QUESTIONS'!B4:G131,3,FALSE))) | H12: =IF(ISERROR(VLOOKUP(D12,'ALL QUESTIONS'!B4:G131,5,FALSE)),"",(VLOOKUP(D12,'ALL QUESTIONS'!B4:G131,5,FALSE))) | I12: =IF(ISERROR(VLOOKUP(D12,'ALL QUESTIONS'!B4:G131,6,FALSE)),"",(VLOOKUP(D12,'ALL QUESTIONS'!B4:G131,6,FALSE)))
D13: 5 | E13: =IF(ISERROR(VLOOKUP(D13,'ALL QUESTIONS'!B5:G132,2,FALSE)),"",(VLOOKUP(D13,'ALL QUESTIONS'!B5:G132,2,FALSE))) | F13: =IF(ISERROR(VLOOKUP(D13,'ALL QUESTIONS'!B5:G132,4,FALSE)),"",(VLOOKUP(D13,'ALL QUESTIONS'!B5:G132,4,FALSE))) | G13: =IF(ISERROR(VLOOKUP(D13,'ALL QUESTIONS'!B5:G132,3,FALSE)),"",(VLOOKUP(D13,'ALL QUESTIONS'!B5:G132,3,FALSE))) | H13: =IF(ISERROR(VLOOKUP(D13,'ALL QUESTIONS'!B5:G132,5,FALSE)),"",(VLOOKUP(D13,'ALL QUESTIONS'!B5:G132,5,FALSE))) | I13: =IF(ISERROR(VLOOKUP(D13,'ALL QUESTIONS'!B5:G132,6,FALSE)),"",(VLOOKUP(D13,'ALL QUESTIONS'!B5:G132,6,FALSE)))
D14: 6 | E14: =IF(ISERROR(VLOOKUP(D14,'ALL QUESTIONS'!B6:G133,2,FALSE)),"",(VLOOKUP(D14,'ALL QUESTIONS'!B6:G133,2,FALSE))) | F14: =IF(ISERROR(VLOOKUP(D14,'ALL QUESTIONS'!B6:G133,4,FALSE)),"",(VLOOKUP(D14,'ALL QUESTIONS'!B6:G133,4,FALSE))) | G14: =IF(ISERROR(VLOOKUP(D14,'ALL QUESTIONS'!B6:G133,3,FALSE)),"",(VLOOKUP(D14,'ALL QUESTIONS'!B6:G133,3,FALSE))) | H14: =IF(ISERROR(VLOOKUP(D14,'ALL QUESTIONS'!B6:G133,5,FALSE)),"",(VLOOKUP(D14,'ALL QUESTIONS'!B6:G133,5,FALSE))) | I14: =IF(ISERROR(VLOOKUP(D14,'ALL QUESTIONS'!B6:G133,6,FALSE)),"",(VLOOKUP(D14,'ALL QUESTIONS'!B6:G133,6,FALSE)))
D15: 7 | E15: =IF(ISERROR(VLOOKUP(D15,'ALL QUESTIONS'!B7:G134,2,FALSE)),"",(VLOOKUP(D15,'ALL QUESTIONS'!B7:G134,2,FALSE))) | F15: =IF(ISERROR(VLOOKUP(D15,'ALL QUESTIONS'!B7:G134,4,FALSE)),"",(VLOOKUP(D15,'ALL QUESTIONS'!B7:G134,4,FALSE))) | G15: =IF(ISERROR(VLOOKUP(D15,'ALL QUESTIONS'!B7:G134,3,FALSE)),"",(VLOOKUP(D15,'ALL QUESTIONS'!B7:G134,3,FALSE))) | H15: =IF(ISERROR(VLOOKUP(D15,'ALL QUESTIONS'!B7:G134,5,FALSE)),"",(VLOOKUP(D15,'ALL QUESTIONS'!B7:G134,5,FALSE))) | I15: =IF(ISERROR(VLOOKUP(D15,'ALL QUESTIONS'!B7:G134,6,FALSE)),"",(VLOOKUP(D15,'ALL QUESTIONS'!B7:G134,6,FALSE)))
D16: 8 | E16: =IF(ISERROR(VLOOKUP(D16,'ALL QUESTIONS'!B8:G135,2,FALSE)),"",(VLOOKUP(D16,'ALL QUESTIONS'!B8:G135,2,FALSE))) | F16: =IF(ISERROR(VLOOKUP(D16,'ALL QUESTIONS'!B8:G135,4,FALSE)),"",(VLOOKUP(D16,'ALL QUESTIONS'!B8:G135,4,FALSE))) | G16: =IF(ISERROR(VLOOKUP(D16,'ALL QUESTIONS'!B8:G135,3,FALSE)),"",(VLOOKUP(D16,'ALL QUESTIONS'!B8:G135,3,FALSE))) | H16: =IF(ISERROR(VLOOKUP(D16,'ALL QUESTIONS'!B8:G135,5,FALSE)),"",(VLOOKUP(D16,'ALL QUESTIONS'!B8:G135,5,FALSE))) | I16: =IF(ISERROR(VLOOKUP(D16,'ALL QUESTIONS'!B8:G135,6,FALSE)),"",(VLOOKUP(D16,'ALL QUESTIONS'!B8:G135,6,FALSE)))
D17: 9 | E17: =IF(ISERROR(VLOOKUP(D17,'ALL QUESTIONS'!B9:G136,2,FALSE)),"",(VLOOKUP(D17,'ALL QUESTIONS'!B9:G136,2,FALSE))) | F17: =IF(ISERROR(VLOOKUP(D17,'ALL QUESTIONS'!B9:G136,4,FALSE)),"",(VLOOKUP(D17,'ALL QUESTIONS'!B9:G136,4,FALSE))) | G17: =IF(ISERROR(VLOOKUP(D17,'ALL QUESTIONS'!B9:G136,3,FALSE)),"",(VLOOKUP(D17,'ALL QUESTIONS'!B9:G136,3,FALSE))) | H17: =IF(ISERROR(VLOOKUP(D17,'ALL QUESTIONS'!B9:G136,5,FALSE)),"",(VLOOKUP(D17,'ALL QUESTIONS'!B9:G136,5,FALSE))) | I17: =IF(ISERROR(VLOOKUP(D17,'ALL QUESTIONS'!B9:G136,6,FALSE)),"",(VLOOKUP(D17,'ALL QUESTIONS'!B9:G136,6,FALSE)))
D18: 10 | E18: =IF(ISERROR(VLOOKUP(D18,'ALL QUESTIONS'!B10:G137,2,FALSE)),"",(VLOOKUP(D18,'ALL QUESTIONS'!B10:G137,2,FALSE))) | F18: =IF(ISERROR(VLOOKUP(D18,'ALL QUESTIONS'!B10:G137,4,FALSE)),"",(VLOOKUP(D18,'ALL QUESTIONS'!B10:G137,4,FALSE))) | G18: =IF(ISERROR(VLOOKUP(D18,'ALL QUESTIONS'!B10:G137,3,FALSE)),"",(VLOOKUP(D18,'ALL QUESTIONS'!B10:G137,3,FALSE))) | H18: =IF(ISERROR(VLOOKUP(D18,'ALL QUESTIONS'!B10:G137,5,FALSE)),"",(VLOOKUP(D18,'ALL QUESTIONS'!B10:G137,5,FALSE))) | I18: =IF(ISERROR(VLOOKUP(D18,'ALL QUESTIONS'!B10:G137,6,FALSE)),"",(VLOOKUP(D18,'ALL QUESTIONS'!B10:G137,6,FALSE)))
D19: 11 | E19: =IF(ISERROR(VLOOKUP(D19,'ALL QUESTIONS'!B11:G138,2,FALSE)),"",(VLOOKUP(D19,'ALL QUESTIONS'!B11:G138,2,FALSE))) | F19: =IF(ISERROR(VLOOKUP(D19,'ALL QUESTIONS'!B11:G138,4,FALSE)),"",(VLOOKUP(D19,'ALL QUESTIONS'!B11:G138,4,FALSE))) | G19: =IF(ISERROR(VLOOKUP(D19,'ALL QUESTIONS'!B11:G138,3,FALSE)),"",(VLOOKUP(D19,'ALL QUESTIONS'!B11:G138,3,FALSE))) | H19: =IF(ISERROR(VLOOKUP(D19,'ALL QUESTIONS'!B11:G138,5,FALSE)),"",(VLOOKUP(D19,'ALL QUESTIONS'!B11:G138,5,FALSE))) | I19: =IF(ISERROR(VLOOKUP(D19,'ALL QUESTIONS'!B11:G138,6,FALSE)),"",(VLOOKUP(D19,'ALL QUESTIONS'!B11:G138,6,FALSE)))
D20: 12 | E20: =IF(ISERROR(VLOOKUP(D20,'ALL QUESTIONS'!B12:G139,2,FALSE)),"",(VLOOKUP(D20,'ALL QUESTIONS'!B12:G139,2,FALSE))) | F20: =IF(ISERROR(VLOOKUP(D20,'ALL QUESTIONS'!B12:G139,4,FALSE)),"",(VLOOKUP(D20,'ALL QUESTIONS'!B12:G139,4,FALSE))) | G20: =IF(ISERROR(VLOOKUP(D20,'ALL QUESTIONS'!B12:G139,3,FALSE)),"",(VLOOKUP(D20,'ALL QUESTIONS'!B12:G139,3,FALSE))) | H20: =IF(ISERROR(VLOOKUP(D20,'ALL QUESTIONS'!B12:G139,5,FALSE)),"",(VLOOKUP(D20,'ALL QUESTIONS'!B12:G139,5,FALSE))) | I20: =IF(ISERROR(VLOOKUP(D20,'ALL QUESTIONS'!B12:G139,6,FALSE)),"",(VLOOKUP(D20,'ALL QUESTIONS'!B12:G139,6,FALSE)))
... D134: 126 | E134: =IF(ISERROR(VLOOKUP(D134,'ALL QUESTIONS'!B126:G253,2,FALSE)),"",(VLOOKUP(D134,'ALL QUESTIONS'!B126:G253,2,FALSE))) | F134: =IF(ISERROR(VLOOKUP(D134,'ALL QUESTIONS'!B126:G253,4,FALSE)),"",(VLOOKUP(D134,'ALL QUESTIONS'!B126:G253,4,FALSE))) | G134: =IF(ISERROR(VLOOKUP(D134,'ALL QUESTIONS'!B126:G253,3,FALSE)),"",(VLOOKUP(D134,'ALL QUESTIONS'!B126:G253,3,FALSE))) | H134: =IF(ISERROR(VLOOKUP(D134,'ALL QUESTIONS'!B126:G253,5,FALSE)),"",(VLOOKUP(D134,'ALL QUESTIONS'!B126:G253,5,FALSE))) | I134: =IF(ISERROR(VLOOKUP(D134,'ALL QUESTIONS'!B126:G253,6,FALSE)),"",(VLOOKUP(D134,'ALL QUESTIONS'!B126:G253,6,FALSE)))

Sheet ALL QUESTIONS
B1: 0 | D1: Section detail | E1: Section Score | F1: Observation | G1: Action
A2: =IF(OR(E2=3, G2="", G2=0), 0, 1) -> 0 | B2: =B1+A2 -> 0 | C2: 4.1A | D2: ='Clause 4'!E8 -> Have internal issues (e.g. culture, resources, processes, performance, sustainability, and resilience factors) affecting your QMS been identified and documented?” | E2: ='Clause 4'!H8 -> 0 | F2: ='Clause 4'!I8 -> 0 | G2: ='Clause 4'!J8
A3: =IF(OR(E3=3, G3="", G3=0), 0, 1) -> 0 | B3: =B2+A3 -> 0 | C3: 4.1B | D3: ='Clause 4'!E9 -> Have external issues (e.g. legal, technological, social, environmental, competitive, or economic) relevant to your organization’s purpose and strategic direction been identified? | E3: ='Clause 4'!H9 -> 0 | F3: ='Clause 4'!I9 -> 0 | G3: ='Clause 4'!J9
A4: =IF(OR(E4=3, G4="", G4=0), 0, 1) -> 0 | B4: =B3+A4 -> 0 | C4: 4.1C | D4: ='Clause 4'!E10 -> Are internal and external issues, including sustainability and resilience factors, reviewed regularly and updated as part of business or management reviews? | E4: ='Clause 4'!H10 -> 0 | F4: ='Clause 4'!I10 -> 0 | G4: ='Clause 4'!J10
A5: =IF(OR(E5=3, G5="", G5=0), 0, 1) -> 0 | B5: =B4+A5 -> 0 | C5: 4.1D | D5: ='Clause 4'!E11 -> Are identified internal and external issues, including sustainability and resilience factors, used to inform risk and opportunity planning (Clause 6.1)? | E5: ='Clause 4'!H11 -> 0 | F5: ='Clause 4'!I11 -> 0 | G5: ='Clause 4'!J11
A6: =IF(OR(E6=3, G6="", G6=0), 0, 1) -> 0 | B6: =B5+A6 -> 0 | C6: 4.2A | D6: ='Clause 4'!E18 -> Have the relevant interested parties, including those linked to sustainability, resilience, and long-term success, been identified (e.g., customers, regulators, suppliers, staff, communities)? | E6: ='Clause 4'!H18 -> 0 | F6: ='Clause 4'!I18 -> 0 | G6: ='Clause 4'!J18
A7: =IF(OR(E7=3, G7="", G7=0), 0, 1) -> 0 | B7: =B6+A7 -> 0 | C7: 4.2B | D7: ='Clause 4'!E19 -> Have the relevant needs, expectations, and requirements of interested parties (including sustainability, compliance, and resilience aspects) been identified and documented? | E7: ='Clause 4'!H19 -> 0 | F7: ='Clause 4'!I19 -> 0 | G7: ='Clause 4'!J19
A8: =IF(OR(E8=3, G8="", G8=0), 0, 1) -> 0 | B8: =B7+A8 -> 0 | C8: 4.2C | D8: ='Clause 4'!E20 -> Are changes in stakeholder needs, expectations, and requirements, including compliance or sustainability factors, monitored regularly? | E8: ='Clause 4'!H20 -> 0 | F8: ='Clause 4'!I20 -> 0 | G8: ='Clause 4'!J20
A9: =IF(OR(E9=3, G9="", G9=0), 0, 1) -> 0 | B9: =B8+A9 -> 0 | C9: 4.2D | D9: ='Clause 4'!E21 -> Are stakeholder needs, expectations, and requirements, including compliance, sustainability, and performance factors, considered in the QMS scope and planning? | E9: ='Clause 4'!H21 -> 0 | F9: ='Clause 4'!I21 -> 0 | G9: ='Clause 4'!J21
A10: =IF(OR(E10=3, G10="", G10=0), 0, 1) -> 0 | B10: =B9+A10 -> 0 | C10: 4.2E | D10: ='Clause 4'!E22 -> Are stakeholder needs, expectations, and requirements, including customer, regulatory, sustainability, and community priorities, communicated to relevant staff and departments? | E10: ='Clause 4'!H22 -> 0 | F10: ='Clause 4'!I22 -> 0 | G10: ='Clause 4'!J22
A11: =IF(OR(E11=3, G11="", G11=0), 0, 1) -> 0 | B11: =B10+A11 -> 0 | C11: 4.3A | D11: ='Clause 4'!E29 -> Has the organization defined the boundaries and applicability of its quality management system, including how it aligns with its context, interested parties, and strategic direction? | E11: ='Clause 4'!H29 -> 0 | F11: ='Clause 4'!I29 -> 0 | G11: ='Clause 4'!J29
A12: =IF(OR(E12=3, G12="", G12=0), 0, 1) -> 0 | B12: =B11+A12 -> 0 | C12: 4.3B | D12: ='Clause 4'!E30 -> Are all relevant products and services, including new or evolving offerings, clearly included within the scope of the QMS | E12: ='Clause 4'!H30 -> 0 | F12: ='Clause 4'!I30 -> 0 | G12: ='Clause 4'!J30
A13: =IF(OR(E13=3, G13="", G13=0), 0, 1) -> 0 | B13: =B12+A13 -> 0 | C13: 4.3C | D13: ='Clause 4'!E31 -> Is the QMS scope documented, maintained, and easily available to relevant stakeholders, including employees, auditors, and external parties where appropriate? | E13: ='Clause 4'!H31 -> 0 | F13: ='Clause 4'!I31 -> 0 | G13: ='Clause 4'!J31
A14: =IF(OR(E14=3, G14="", G14=0), 0, 1) -> 0 | B14: =B13+A14 -> 0 | C14: 4.3D | D14: ='Clause 4'!E32 -> Is the QMS scope communicated to relevant stakeholders, including employees, auditors, and external interested parties where appropriate? | E14: ='Clause 4'!H32 -> 0 | F14: ='Clause 4'!I32 -> 0 | G14: ='Clause 4'!J32
A15: =IF(OR(E15=3, G15="", G15=0), 0, 1) -> 0 | B15: =B14+A15 -> 0 | C15: 4.4A | D15: ='Clause 4'!E39 -> Has the organization determined the processes needed for the QMS and their application throughout the organization? | E15: ='Clause 4'!H39 -> 0 | F15: ='Clause 4'!I39 -> 0 | G15: ='Clause 4'!J39
A16: =IF(OR(E16=3, G16="", G16=0), 0, 1) -> 0 | B16: =B15+A16 -> 0 | C16: 4.4B | D16: ='Clause 4'!E40 -> Are the inputs and expected outputs of each process defined? | E16: ='Clause 4'!H40 -> 0 | F16: ='Clause 4'!I40 -> 0 | G16: ='Clause 4'!J40
A17: =IF(OR(E17=3, G17="", G17=0), 0, 1) -> 0 | B17: =B16+A17 -> 0 | C17: 4.4C | D17: ='Clause 4'!E41 -> Have responsibilities and authorities for each process been assigned? | E17: ='Clause 4'!H41 -> 0 | F17: ='Clause 4'!I41 -> 0 | G17: ='Clause 4'!J41
A18: =IF(OR(E18=3, G18="", G18=0), 0, 1) -> 0 | B18: =B17+A18 -> 0 | C18: 4.4D | D18: ='Clause 4'!E42 -> Are performance indicators or methods for measuring the processes established? | E18: ='Clause 4'!H42 -> 0 | F18: ='Clause 4'!I42 -> 0 | G18: ='Clause 4'!J42
A19: =IF(OR(E19=3, G19="", G19=0), 0, 1) -> 0 | B19: =B18+A19 -> 0 | C19: 4.4E | D19: ='Clause 4'!E43 -> Are risks and opportunities for each process identified, documented, and addressed to enhance performance and resilience? | E19: ='Clause 4'!H43 -> 0 | F19: ='Clause 4'!I43 -> 0 | G19: ='Clause 4'!J43
A20: =IF(OR(E20=3, G20="", G20=0), 0, 1) -> 0 | B20: =B19+A20 -> 0 | C20: 4.4F | D20: ='Clause 4'!E44 -> Are processes regularly reviewed, maintained, and improved as part of the QMS to support performance, resilience, and continual improvement? | E20: ='Clause 4'!H44 -> 0 | F20: ='Clause 4'!I44 -> 0 | G20: ='Clause 4'!J44
A21: =IF(OR(E21=3, G21="", G21=0), 0, 1) -> #REF! | B21: =B20+A21 -> #REF! | C21: 5.1A | D21: =#REF! -> #REF! | E21: =#REF! -> #REF! | F21: =#REF! -> #REF! | G21: =#REF! -> #REF!
A22: =IF(OR(E22=3, G22="", G22=0), 0, 1) -> #REF! | B22: =B21+A22 -> #REF! | C22: 5.1B | D22: =#REF! -> #REF! | E22: =#REF! -> #REF! | F22: =#REF! -> #REF! | G22: =#REF! -> #REF!
A23: =IF(OR(E23=3, G23="", G23=0), 0, 1) -> #REF! | B23: =B22+A23 -> #REF! | C23: 5.1C | D23: =#REF! -> #REF! | E23: =#REF! -> #REF! | F23: =#REF! -> #REF! | G23: =#REF! -> #REF!
A24: =IF(OR(E24=3, G24="", G24=0), 0, 1) -> #REF! | B24: =B23+A24 -> #REF! | C24: 5.1D | D24: =#REF! -> #REF! | E24: =#REF! -> #REF! | F24: =#REF! -> #REF! | G24: =#REF! -> #REF!
A25: =IF(OR(E25=3, G25="", G25=0), 0, 1) -> #REF! | B25: =B24+A25 -> #REF! | C25: 5.2A | D25: =#REF! -> #REF! | E25: =#REF! -> #REF! | F25: =#REF! -> #REF! | G25: =#REF! -> #REF!
A26: =IF(OR(E26=3, G26="", G26=0), 0, 1) -> #REF! | B26: =B25+A26 -> #REF! | C26: 5.2B | D26: =#REF! -> #REF! | E26: =#REF! -> #REF! | F26: =#REF! -> #REF! | G26: =#REF! -> #REF!
A27: =IF(OR(E27=3, G27="", G27=0), 0, 1) -> #REF! | B27: =B26+A27 -> #REF! | C27: 5.2C | D27: =#REF! -> #REF! | E27: =#REF! -> #REF! | F27: =#REF! -> #REF! | G27: =#REF! -> #REF!
A28: =IF(OR(E28=3, G28="", G28=0), 0, 1) -> #REF! | B28: =B27+A28 -> #REF! | C28: 5.2D | D28: =#REF! -> #REF! | E28: =#REF! -> #REF! | F28: =#REF! -> #REF! | G28: =#REF! -> #REF!
A29: =IF(OR(E29=3, G29="", G29=0), 0, 1) -> #REF! | B29: =B28+A29 -> #REF! | C29: 5.3A | D29: =#REF! -> #REF! | E29: =#REF! -> #REF! | F29: =#REF! -> #REF! | G29: =#REF! -> #REF!
A30: =IF(OR(E30=3, G30="", G30=0), 0, 1) -> #REF! | B30: =B29+A30 -> #REF! | C30: 5.3B | D30: =#REF! -> #REF! | E30: =#REF! -> #REF! | F30: =#REF! -> #REF! | G30: =#REF! -> #REF!
A31: =IF(OR(E31=3, G31="", G31=0), 0, 1) -> #REF! | B31: =B30+A31 -> #REF! | C31: 5.3C | D31: =#REF! -> #REF! | E31: =#REF! -> #REF! | F31: =#REF! -> #REF! | G31: =#REF! -> #REF!
A32: =IF(OR(E32=3, G32="", G32=0), 0, 1) -> #REF! | B32: =B31+A32 -> #REF! | C32: 5.3D | D32: =#REF! -> #REF! | E32: =#REF! -> #REF! | F32: =#REF! -> #REF! | G32: =#REF! -> #REF!
... A63: =IF(OR(E63=3, G63="", G63=0), 0, 1) -> #REF! | B63: =B62+A63 -> #REF! | C63: 7.4B | D63: =#REF! -> #REF! | E63: =#REF! -> #REF! | F63: =#REF! -> #REF! | G63: =#REF! -> #REF!
A64: =IF(OR(E64=3, G64="", G64=0), 0, 1) -> #REF! | B64: =B63+A64 -> #REF! | C64: 7.4C | D64: =#REF! -> #REF! | E64: =#REF! -> #REF! | F64: =#REF! -> #REF!
A65: =IF(OR(E65=3, G65="", G65=0), 0, 1) -> #REF! | B65: =B64+A65 -> #REF! | C65: 7.4D | D65: =#REF! -> #REF! | E65: =#REF! -> #REF! | F65: =#REF! -> #REF!
A66: =IF(OR(E66=3, G66="", G66=0), 0, 1) -> #REF! | B66: =B65+A66 -> #REF! | C66: 7.5A | D66: =#REF! -> #REF! | E66: =#REF! -> #REF! | F66: =#REF! -> #REF!
A67: =IF(OR(E67=3, G67="", G67=0), 0, 1) -> #REF! | B67: =B66+A67 -> #REF! | C67: 7.5B | D67: =#REF! -> #REF! | E67: =#REF! -> #REF! | F67: =#REF! -> #REF!
A68: =IF(OR(E68=3, G68="", G68=0), 0, 1) -> #REF! | B68: =B67+A68 -> #REF! | C68: 7.5C | D68: =#REF! -> #REF! | E68: =#REF! -> #REF! | F68: =#REF! -> #REF!
A69: =IF(OR(E69=3, G69="", G69=0), 0, 1) -> #REF! | B69: =B68+A69 -> #REF! | C69: 7.5D | D69: =#REF! -> #REF! | E69: =#REF! -> #REF! | F69: =#REF! -> #REF!
A70: =IF(OR(E70=3, G70="", G70=0), 0, 1) -> #REF! | B70: =B69+A70 -> #REF! | C70: 7.5E | D70: =#REF! -> #REF! | E70: =#REF! -> #REF! | F70: =#REF! -> #REF! | G70: =#REF! -> #REF!
...

Sheet Data
A1: Clause 4: Context of the Organization | B1: ='Audit Scoring Detail'!S10 -> 0
A3: Clause 5: Leadership and Commitment | B3: ='Audit Scoring Detail'!S17 -> 0
A5: Clause 6: Planning | B5: ='Audit Scoring Detail'!S24 -> 0
A7: Clause 7: Support | B7: ='Audit Scoring Detail'!S31 -> 0
A9: Clause 8: Operation | B9: ='Audit Scoring Detail'!S38 -> 0
A11: Clause 9: Performance Evaluation | B11: ='Audit Scoring Detail'!S45 -> 0
A13: Clause 10: Improvement | B13: ='Audit Scoring Detail'!S53 -> 0
